Workbook

Sheet Raw Data
A1: paul baker | B1: Date | C1: Customer_ID | D1: Customer_Name | E1: Product_ID | F1: Product_Name | G1: Category | H1: Quantity | I1: Unit_Price | J1: Payment_Method | K1: Region | L1: Customer_Segment | M1: Customer_Since | N1: Total_Amount
B2: 2024-04-11 | C2: CUST023 | D2: Paul Baker | E2: P009 | F2: Monitor | G2: Electronics | H2: 3 | I2: 249.99 | J2: Cash | K2: Central | L2: Basic | M2: 2021-08-17 | N2: 749.97
A3: TRX0023 | B3: 2024-04-14 | C3: CUST013 | D3: Joseph Jackson | E3: P009 | F3: Monitor | G3: Electronics | H3: 3 | I3: 249.99 | J3: Credit Card | K3: Central | L3: Premium | M3: 2022-01-14 | N3: 749.97
A4: TRX0139 | B4: 2024-04-17 | C4: CUST021 | D4: Kevin Scott | E4: P005 | F4: Blender | G4: Appliances | H4: 3 | I4: 59.99 | J4: PayPal | K4: South | L4: Standard | M4: 2023-12-02 | N4: 179.97
A5: TRX0043 | B5: 2024-04-18 | C5: CUST046 | D5: Kathleen Bennett | E5: P005 | F5: Blender | G5: Appliances | H5: 3 | I5: 59.99 | J5: Cash | K5: North | L5: Premium | M5: 2023-07-07 | N5: 179.97
A6: TRX0212 | B6: 2024-04-18 | C6: CUST003 | D6: Michael Brown | E6: P008 | F6: Bookshelf | G6: Furniture | H6: 5 | I6: 149.99 | J6: Credit Card | K6: North | L6: Premium | M6: 2024-01-04 | N6: 749.95
A7: TRX0092 | B7: 2024-04-21 | C7: CUST024 | D7: Dorothy Nelson | E7: P005 | F7: Blender | G7: Appliances | H7: 2 | I7: 59.99 | J7: Cash | K7: West | L7: Standard | M7: 2022-07-04 | N7: 119.98
A8: TRX0193 | B8: 2024-04-21 | C8: CUST024 | D8: Dorothy Nelson | E8: P003 | F8: Headphones | G8: Electronics | H8: 5 | I8: 149.99 | J8: Credit Card | K8: Central | L8: Standard | M8: 2021-08-10 | N8: 749.95
A9: TRX0240 | B9: 2024-04-21 | C9: CUST017 | D9: Charles Allen | E9: P005 | F9: Blender | G9: Appliances | H9: 3 | I9: 59.99 | J9: Debit Card | K9: South | L9: Basic | M9: 2023-03-22 | N9: 179.97
A10: TRX0135 | B10: 2024-04-23 | C10: CUST009 | D10: Robert Thomas | E10: P001 | F10: Laptop | G10: Electronics | H10: 3 | I10: 899.99 | J10: PayPal | K10: East | L10: Standard | M10: 2024-01-08 | N10: 2699.97
A11: TRX0185 | B11: 2024-04-26 | C11: CUST026 | D11: Karen Hill | E11: P005 | F11: Blender | G11: Appliances | H11: 3 | I11: 59.99 | J11: Cash | K11: West | L11: Premium | M11: 2023-10-08 | N11: 179.97
A12: TRX0138 | B12: 2024-04-26 | C12: CUST022 | D12: Susan Green | E12: P008 | F12: Bookshelf | G12: Furniture | H12: 1 | I12: 149.99 | J12: Credit Card | K12: West | L12: Standard | M12: 2023-06-26 | N12: 149.99
A13: TRX0209 | B13: 2024-04-26 | C13: CUST046 | D13: Kathleen Bennett | E13: P008 | F13: Bookshelf | G13: Furniture | H13: 5 | I13: 149.99 | J13: Debit Card | K13: North | L13: Basic | M13: 2022-09-26 | N13: 749.95
A14: TRX0246 | B14: 2024-04-26 | C14: CUST041 | D14: Peter Richardson | E14: P008 | F14: Bookshelf | G14: Furniture | H14: 3 | I14: 149.99 | J14: Cash | K14: North | L14: Premium | M14: 2022-09-02 | N14: 449.97
... A251: TRX0064 | B251: 2025-04-11 | C251: CUST031 | D251: Steven Turner | E251: P010 | F251: Keyboard | G251: Electronics | H251: 3 | I251: 89.99 | J251: Debit Card | K251: North | L251: Premium | M251: 2022-11-13 | N251: 269.97

Sheet Analysis
A1: DATA INTELLIGENCE — ANALYSIS & FORMULAS
A3: 1. DATE & TIME FUNCTIONS | E3: TODAY, NOW, DATEDIF, EOMONTH functions demonstrated below | F3: 3. GROUPBY — Revenue & Orders by Category (SUMIF/COUNTIF)
A4: Formula Description | B4: Formula Used | C4: Result | F4: Category | G4: Total Revenue | H4: # Orders | I4: Avg Order Value | J4: % of Total Revenue
A5: Today's Date | B5: =TODAY() -> 46109 | C5: =TODAY() -> 46109 | F5: Electronics | G5: =SUMIF('Raw Data'!G:G,F5,'Raw Data'!N:N) -> 171756.05 | H5: =COUNTIF('Raw Data'!G:G,F5) -> 131 | I5: =IFERROR(G5/H5,0) -> 1311.1149 | J5: =IFERROR(G5/SUM(G5:G7),0) -> 0.74939657
A6: Current DateTime | B6: =NOW() -> 46109.666 | C6: =NOW() -> 46109.666 | F6: Furniture | G6: =SUMIF('Raw Data'!G:G,F6,'Raw Data'!N:N) -> 49097.68 | H6: =COUNTIF('Raw Data'!G:G,F6) -> 76 | I6: =IFERROR(G6/H6,0) -> 646.02211 | J6: =IFERROR(G6/SUM(G5:G7),0) -> 0.2142203
A7: End of Current Month | B7: =EOMONTH(TODAY(),0) -> 46112 | C7: =EOMONTH(TODAY(),0) -> 46112 | F7: Appliances | G7: =SUMIF('Raw Data'!G:G,F7,'Raw Data'!N:N) -> 8338.74 | H7: =COUNTIF('Raw Data'!G:G,F7) -> 43 | I7: =IFERROR(G7/H7,0) -> 193.92419 | J7: =IFERROR(G7/SUM(G5:G7),0) -> 0.036383132
A8: End of Next Month | B8: =EOMONTH(TODAY(),1) -> 46142 | C8: =EOMONTH(TODAY(),1) -> 46142 | F8: TOTAL | G8: =SUM(G5:G7) -> 229192.47 | H8: =SUM(H5:H7) -> 250 | I8: =IFERROR(G8/H8,0) -> 916.76988
A9: Days Since Dataset Start (Apr 11 2024) | B9: =DATEDIF(DATE(2024,4,11),TODAY(),"D") -> 716 | C9: =DATEDIF(DATE(2024,4,11),TODAY(),"D") -> 716
A10: Months Since Dataset Start | B10: =DATEDIF(DATE(2024,4,11),TODAY(),"M") -> 23 | C10: =DATEDIF(DATE(2024,4,11),TODAY(),"M") -> 23 | F10: 4. GROUPBY — Revenue by Region (SUMIF)
A11: Years Since Dataset Start | B11: =DATEDIF(DATE(2024,4,11),TODAY(),"Y") -> 1 | C11: =DATEDIF(DATE(2024,4,11),TODAY(),"Y") -> 1 | F11: Region | G11: Revenue | H11: Transactions | I11: Avg Ticket
A12: Dataset Span (Days) | B12: =DATEDIF(DATE(2024,4,11),DATE(2025,4,11),"D") -> 365 | C12: =DATEDIF(DATE(2024,4,11),DATE(2025,4,11),"D") -> 365 | F12: North | G12: =SUMIF('Raw Data'!K:K,F12,'Raw Data'!N:N) -> 50808.31 | H12: =COUNTIF('Raw Data'!K:K,F12) -> 59 | I12: =IFERROR(G12/H12,0) -> 861.1578
A13: Timestamp (NOW) | B13: =TEXT(NOW(),"DD-MMM-YYYY HH:MM:SS") -> 28-Mar-2026 15:59:27 | C13: =TEXT(NOW(),"DD-MMM-YYYY HH:MM:SS") -> 28-Mar-2026 15:59:27 | F13: South | G13: =SUMIF('Raw Data'!K:K,F13,'Raw Data'!N:N) -> 36398.75 | H13: =COUNTIF('Raw Data'!K:K,F13) -> 42 | I13: =IFERROR(G13/H13,0) -> 866.6369
F14: East | G14: =SUMIF('Raw Data'!K:K,F14,'Raw Data'!N:N) -> 59288.39 | H14: =COUNTIF('Raw Data'!K:K,F14) -> 48 | I14: =IFERROR(G14/H14,0) -> 1235.1748
A15: 2. FILTER FUNCTION — Premium Customers | F15: West | G15: =SUMIF('Raw Data'!K:K,F15,'Raw Data'!N:N) -> 41408.68 | H15: =COUNTIF('Raw Data'!K:K,F15) -> 47 | I15: =IFERROR(G15/H15,0) -> 881.03574
A16: Transaction_ID | B16: Customer_Name | C16: Category | D16: Total_Amount | F16: Central | G16: =SUMIF('Raw Data'!K:K,F16,'Raw Data'!N:N) -> 41288.34 | H16: =COUNTIF('Raw Data'!K:K,F16) -> 54 | I16: =IFERROR(G16/H16,0) -> 764.59889
A17: See Raw Data filtered by Segment=Premium | B17: =COUNTIF('Raw Data'!L:L,"Premium") & " Premium transactions found" -> 95 Premium transactions found | C17: =SUMIF('Raw Data'!L:L,"Premium",'Raw Data'!N:N) -> 84657.12
F18: 6. HIGH-VALUE CUSTOMERS (SUMIF + RANK)
F19: Customer_ID | G19: Customer_Name | H19: Total Spent | I19: # Orders | J19: Avg Order | K19: Segment | L19: Customer Abbrev.
A20: 5. MONTHLY REVENUE (SUMPRODUCT) | F20: CUST025 | G20: Mark Carter | H20: =SUMIF('Raw Data'!C:C,F20,'Raw Data'!N:N) -> 15659.65 | I20: =COUNTIF('Raw Data'!C:C,F20) -> 12 | J20: =IFERROR(H20/I20,0) -> 1304.9708 | K20: =IFERROR(INDEX('Raw Data'!L:L,MATCH(F20,'Raw Data'!C:C,0)),"") -> Premium | L20: =UPPER(LEFT(G20,1))&"."&UPPER(MID(G20,FIND(" ",G20)+1,1))&"." -> M.C.
A21: Month | B21: Month-Year | C21: Revenue | D21: Orders | F21: CUST026 | G21: Karen Hill | H21: =SUMIF('Raw Data'!C:C,F21,'Raw Data'!N:N) -> 8009.77 | I21: =COUNTIF('Raw Data'!C:C,F21) -> 8 | J21: =IFERROR(H21/I21,0) -> 1001.2212 | K21: =IFERROR(INDEX('Raw Data'!L:L,MATCH(F21,'Raw Data'!C:C,0)),"") -> Premium | L21: =UPPER(LEFT(G21,1))&"."&UPPER(MID(G21,FIND(" ",G21)+1,1))&"." -> K.H.
A22: 4 | B22: Apr-2024 | C22: =SUMPRODUCT((MONTH('Raw Data'!B$2:B$251)=4)*(YEAR('Raw Data'!B$2:B$251)=2024)*('Raw Data'!N$2:N$251)) -> 20919.33 | D22: =SUMPRODUCT((MONTH('Raw Data'!B$2:B$251)=4)*(YEAR('Raw Data'!B$2:B$251)=2024)*1) -> 21 | F22: CUST012 | G22: Patricia Moore | H22: =SUMIF('Raw Data'!C:C,F22,'Raw Data'!N:N) -> 9799.73 | I22: =COUNTIF('Raw Data'!C:C,F22) -> 8 | J22: =IFERROR(H22/I22,0) -> 1224.9662 | K22: =IFERROR(INDEX('Raw Data'!L:L,MATCH(F22,'Raw Data'!C:C,0)),"") -> Standard | L22: =UPPER(LEFT(G22,1))&"."&UPPER(MID(G22,FIND(" ",G22)+1,1))&"." -> P.M.
A23: 5 | B23: May-2024 | C23: =SUMPRODUCT((MONTH('Raw Data'!B$2:B$251)=5)*(YEAR('Raw Data'!B$2:B$251)=2024)*('Raw Data'!N$2:N$251)) -> 17039.35 | D23: =SUMPRODUCT((MONTH('Raw Data'!B$2:B$251)=5)*(YEAR('Raw Data'!B$2:B$251)=2024)*1) -> 19 | F23: CUST003 | G23: Michael Brown | H23: =SUMIF('Raw Data'!C:C,F23,'Raw Data'!N:N) -> 6169.74 | I23: =COUNTIF('Raw Data'!C:C,F23) -> 9 | J23: =IFERROR(H23/I23,0) -> 685.52667 | K23: =IFERROR(INDEX('Raw Data'!L:L,MATCH(F23,'Raw Data'!C:C,0)),"") -> Premium | L23: =UPPER(LEFT(G23,1))&"."&UPPER(MID(G23,FIND(" ",G23)+1,1))&"." -> M.B.
A24: 6 | B24: Jun-2024 | C24: =SUMPRODUCT((MONTH('Raw Data'!B$2:B$251)=6)*(YEAR('Raw Data'!B$2:B$251)=2024)*('Raw Data'!N$2:N$251)) -> 19299.45 | D24: =SUMPRODUCT((MONTH('Raw Data'!B$2:B$251)=6)*(YEAR('Raw Data'!B$2:B$251)=2024)*1) -> 19 | F24: CUST013 | G24: Joseph Jackson | H24: =SUMIF('Raw Data'!C:C,F24,'Raw Data'!N:N) -> 6949.84 | I24: =COUNTIF('Raw Data'!C:C,F24) -> 5 | J24: =IFERROR(H24/I24,0) -> 1389.968 | K24: =IFERROR(INDEX('Raw Data'!L:L,MATCH(F24,'Raw Data'!C:C,0)),"") -> Premium | L24: =UPPER(LEFT(G24,1))&"."&UPPER(MID(G24,FIND(" ",G24)+1,1))&"." -> J.J.
A25: 7 | B25: Jul-2024 | C25: =SUMPRODUCT((MONTH('Raw Data'!B$2:B$251)=7)*(YEAR('Raw Data'!B$2:B$251)=2024)*('Raw Data'!N$2:N$251)) -> 18479.4 | D25: =SUMPRODUCT((MONTH('Raw Data'!B$2:B$251)=7)*(YEAR('Raw Data'!B$2:B$251)=2024)*1) -> 24 | F25: CUST029 | G25: Edward Mitchell | H25: =SUMIF('Raw Data'!C:C,F25,'Raw Data'!N:N) -> 11919.77 | I25: =COUNTIF('Raw Data'!C:C,F25) -> 6 | J25: =IFERROR(H25/I25,0) -> 1986.6283 | K25: =IFERROR(INDEX('Raw Data'!L:L,MATCH(F25,'Raw Data'!C:C,0)),"") -> Standard | L25: =UPPER(LEFT(G25,1))&"."&UPPER(MID(G25,FIND(" ",G25)+1,1))&"." -> E.M.
A26: 8 | B26: Aug-2024 | C26: =SUMPRODUCT((MONTH('Raw Data'!B$2:B$251)=8)*(YEAR('Raw Data'!B$2:B$251)=2024)*('Raw Data'!N$2:N$251)) -> 15759.43 | D26: =SUMPRODUCT((MONTH('Raw Data'!B$2:B$251)=8)*(YEAR('Raw Data'!B$2:B$251)=2024)*1) -> 18 | F26: CUST030 | G26: Helen Roberts | H26: =SUMIF('Raw Data'!C:C,F26,'Raw Data'!N:N) -> 6459.79 | I26: =COUNTIF('Raw Data'!C:C,F26) -> 7 | J26: =IFERROR(H26/I26,0) -> 922.82714 | K26: =IFERROR(INDEX('Raw Data'!L:L,MATCH(F26,'Raw Data'!C:C,0)),"") -> Standard | L26: =UPPER(LEFT(G26,1))&"."&UPPER(MID(G26,FIND(" ",G26)+1,1))&"." -> H.R.
A27: 9 | B27: Sep-2024 | C27: =SUMPRODUCT((MONTH('Raw Data'!B$2:B$251)=9)*(YEAR('Raw Data'!B$2:B$251)=2024)*('Raw Data'!N$2:N$251)) -> 12989.51 | D27: =SUMPRODUCT((MONTH('Raw Data'!B$2:B$251)=9)*(YEAR('Raw Data'!B$2:B$251)=2024)*1) -> 19 | F27: CUST019 | G27: Daniel King | H27: =SUMIF('Raw Data'!C:C,F27,'Raw Data'!N:N) -> 7309.8 | I27: =COUNTIF('Raw Data'!C:C,F27) -> 7 | J27: =IFERROR(H27/I27,0) -> 1044.2571 | K27: =IFERROR(INDEX('Raw Data'!L:L,MATCH(F27,'Raw Data'!C:C,0)),"") -> Standard | L27: =UPPER(LEFT(G27,1))&"."&UPPER(MID(G27,FIND(" ",G27)+1,1))&"." -> D.K.
A28: 10 | B28: Oct-2024 | C28: =SUMPRODUCT((MONTH('Raw Data'!B$2:B$251)=10)*(YEAR('Raw Data'!B$2:B$251)=2024)*('Raw Data'!N$2:N$251)) -> 20609.52 | D28: =SUMPRODUCT((MONTH('Raw Data'!B$2:B$251)=10)*(YEAR('Raw Data'!B$2:B$251)=2024)*1) -> 16 | F28: CUST039 | G28: Lawrence Reed | H28: =SUMIF('Raw Data'!C:C,F28,'Raw Data'!N:N) -> 6989.77 | I28: =COUNTIF('Raw Data'!C:C,F28) -> 8 | J28: =IFERROR(H28/I28,0) -> 873.72125 | K28: =IFERROR(INDEX('Raw Data'!L:L,MATCH(F28,'Raw Data'!C:C,0)),"") -> Premium | L28: =UPPER(LEFT(G28,1))&"."&UPPER(MID(G28,FIND(" ",G28)+1,1))&"." -> L.R.
A29: 11 | B29: Nov-2024 | C29: =SUMPRODUCT((MONTH('Raw Data'!B$2:B$251)=11)*(YEAR('Raw Data'!B$2:B$251)=2024)*('Raw Data'!N$2:N$251)) -> 12309.44 | D29: =SUMPRODUCT((MONTH('Raw Data'!B$2:B$251)=11)*(YEAR('Raw Data'!B$2:B$251)=2024)*1) -> 17 | F29: CUST017 | G29: Charles Allen | H29: =SUMIF('Raw Data'!C:C,F29,'Raw Data'!N:N) -> 5089.73 | I29: =COUNTIF('Raw Data'!C:C,F29) -> 9 | J29: =IFERROR(H29/I29,0) -> 565.52556 | K29: =IFERROR(INDEX('Raw Data'!L:L,MATCH(F29,'Raw Data'!C:C,0)),"") -> Basic | L29: =UPPER(LEFT(G29,1))&"."&UPPER(MID(G29,FIND(" ",G29)+1,1))&"." -> C.A.
A30: 12 | B30: Dec-2024 | C30: =SUMPRODUCT((MONTH('Raw Data'!B$2:B$251)=12)*(YEAR('Raw Data'!B$2:B$251)=2024)*('Raw Data'!N$2:N$251)) -> 23039.3 | D30: =SUMPRODUCT((MONTH('Raw Data'!B$2:B$251)=12)*(YEAR('Raw Data'!B$2:B$251)=2024)*1) -> 25 | F30: CUST023 | G30: Paul Baker | H30: =SUMIF('Raw Data'!C:C,F30,'Raw Data'!N:N) -> 8309.74 | I30: =COUNTIF('Raw Data'!C:C,F30) -> 8 | J30: =IFERROR(H30/I30,0) -> 1038.7175 | K30: =IFERROR(INDEX('Raw Data'!L:L,MATCH(F30,'Raw Data'!C:C,0)),"") -> Basic | L30: =UPPER(LEFT(G30,1))&"."&UPPER(MID(G30,FIND(" ",G30)+1,1))&"." -> P.B.
A31: 1 | B31: Jan-2025 | C31: =SUMPRODUCT((MONTH('Raw Data'!B$2:B$251)=1)*(YEAR('Raw Data'!B$2:B$251)=2025)*('Raw Data'!N$2:N$251)) -> 25799.15 | D31: =SUMPRODUCT((MONTH('Raw Data'!B$2:B$251)=1)*(YEAR('Raw Data'!B$2:B$251)=2025)*1) -> 26 | F31: CUST024 | G31: Dorothy Nelson | H31: =SUMIF('Raw Data'!C:C,F31,'Raw Data'!N:N) -> 8269.79 | I31: =COUNTIF('Raw Data'!C:C,F31) -> 6 | J31: =IFERROR(H31/I31,0) -> 1378.2983 | K31: =IFERROR(INDEX('Raw Data'!L:L,MATCH(F31,'Raw Data'!C:C,0)),"") -> Standard | L31: =UPPER(LEFT(G31,1))&"."&UPPER(MID(G31,FIND(" ",G31)+1,1))&"." -> D.N.
A32: 2 | B32: Feb-2025 | C32: =SUMPRODUCT((MONTH('Raw Data'!B$2:B$251)=2)*(YEAR('Raw Data'!B$2:B$251)=2025)*('Raw Data'!N$2:N$251)) -> 16069.38 | D32: =SUMPRODUCT((MONTH('Raw Data'!B$2:B$251)=2)*(YEAR('Raw Data'!B$2:B$251)=2025)*1) -> 20
A33: 3 | B33: Mar-2025 | C33: =SUMPRODUCT((MONTH('Raw Data'!B$2:B$251)=3)*(YEAR('Raw Data'!B$2:B$251)=2025)*('Raw Data'!N$2:N$251)) -> 19899.38 | D33: =SUMPRODUCT((MONTH('Raw Data'!B$2:B$251)=3)*(YEAR('Raw Data'!B$2:B$251)=2025)*1) -> 19 | F33: 8. PAYMENT METHOD ANALYSIS
A34: 4 | B34: Apr-2025 | C34: =SUMPRODUCT((MONTH('Raw Data'!B$2:B$251)=4)*(YEAR('Raw Data'!B$2:B$251)=2025)*('Raw Data'!N$2:N$251)) -> 6979.83 | D34: =SUMPRODUCT((MONTH('Raw Data'!B$2:B$251)=4)*(YEAR('Raw Data'!B$2:B$251)=2025)*1) -> 7 | F34: Payment Method | G34: Count | H34: Revenue | I34: % Share
F35: Cash | G35: =COUNTIF('Raw Data'!J:J,F35) -> 76 | H35: =SUMIF('Raw Data'!J:J,F35,'Raw Data'!N:N) -> 57427.79 | I35: =IFERROR(H35/SUM(H35:H38),0) -> 0.25056578
A36: 7. MOST FREQUENTLY PURCHASED PRODUCT | F36: Credit Card | G36: =COUNTIF('Raw Data'!J:J,F36) -> 68 | H36: =SUMIF('Raw Data'!J:J,F36,'Raw Data'!N:N) -> 61447.96 | I36: =IFERROR(H36/SUM(H35:H38),0) -> 0.26810636
A37: Product | B37: Count | C37: Revenue | D37: Frequency Rank | F37: Debit Card | G37: =COUNTIF('Raw Data'!J:J,F37) -> 54 | H37: =SUMIF('Raw Data'!J:J,F37,'Raw Data'!N:N) -> 52118.31 | I37: =IFERROR(H37/SUM(H35:H38),0) -> 0.22739975
A38: Laptop | B38: =COUNTIF('Raw Data'!F:F,A38) -> 24 | C38: =SUMIF('Raw Data'!F:F,A38,'Raw Data'!N:N) -> 67499.25 | D38: =RANK(B38,B$38:B$47,0) -> 7 | F38: PayPal | G38: =COUNTIF('Raw Data'!J:J,F38) -> 52 | H38: =SUMIF('Raw Data'!J:J,F38,'Raw Data'!N:N) -> 58198.41 | I38: =IFERROR(H38/SUM(H35:H38),0) -> 0.25392811
A39: Smartphone | B39: =COUNTIF('Raw Data'!F:F,A39) -> 31 | C39: =SUMIF('Raw Data'!F:F,A39,'Raw Data'!N:N) -> 67199.04 | D39: =RANK(B39,B$38:B$47,0) -> 3
A40: Headphones | B40: =COUNTIF('Raw Data'!F:F,A40) -> 16 | C40: =SUMIF('Raw Data'!F:F,A40,'Raw Data'!N:N) -> 7049.53 | D40: =RANK(B40,B$38:B$47,0) -> 8 | F40: 9. WHAT-IF ANALYSIS — Revenue Scenarios
A41: Coffee Maker | B41: =COUNTIF('Raw Data'!F:F,A41) -> 14 | C41: =SUMIF('Raw Data'!F:F,A41,'Raw Data'!N:N) -> 3119.61 | D41: =RANK(B41,B$38:B$47,0) -> 10 | F41: Base Total Revenue | G41: =SUMIF('Raw Data'!G:G,"Electronics",'Raw Data'!N:N)+SUMIF('Raw Data'!G:G,"Furniture",'Raw Data'!N:N)+SUMIF('Raw Data'!G:G,"Appliances",'Raw Data'!N:N) -> 229192.47
...

Sheet Visualizations
A1: CHARTS & VISUALIZATIONS
A3: Revenue by Category | E3: Payment Methods
A4: Category | B4: Revenue | C4: Orders | E4: Method | F4: Count | G4: Revenue
A5: Electronics | B5: =SUMIF('Raw Data'!G:G,"Electronics",'Raw Data'!N:N) -> 171756.05 | C5: =COUNTIF('Raw Data'!G:G,"Electronics") -> 131 | E5: Cash | F5: =COUNTIF('Raw Data'!J:J,E5) -> 76 | G5: =SUMIF('Raw Data'!J:J,E5,'Raw Data'!N:N) -> 57427.79
A6: Furniture | B6: =SUMIF('Raw Data'!G:G,"Furniture",'Raw Data'!N:N) -> 49097.68 | C6: =COUNTIF('Raw Data'!G:G,"Furniture") -> 76 | E6: Credit Card | F6: =COUNTIF('Raw Data'!J:J,E6) -> 68 | G6: =SUMIF('Raw Data'!J:J,E6,'Raw Data'!N:N) -> 61447.96
A7: Appliances | B7: =SUMIF('Raw Data'!G:G,"Appliances",'Raw Data'!N:N) -> 8338.74 | C7: =COUNTIF('Raw Data'!G:G,"Appliances") -> 43 | E7: Debit Card | F7: =COUNTIF('Raw Data'!J:J,E7) -> 54 | G7: =SUMIF('Raw Data'!J:J,E7,'Raw Data'!N:N) -> 52118.31
E8: PayPal | F8: =COUNTIF('Raw Data'!J:J,E8) -> 52 | G8: =SUMIF('Raw Data'!J:J,E8,'Raw Data'!N:N) -> 58198.41
A9: Revenue by Region
A10: Region | B10: Revenue
A11: North | B11: =SUMIF('Raw Data'!K:K,A11,'Raw Data'!N:N) -> 50808.31
A12: South | B12: =SUMIF('Raw Data'!K:K,A12,'Raw Data'!N:N) -> 36398.75
A13: East | B13: =SUMIF('Raw Data'!K:K,A13,'Raw Data'!N:N) -> 59288.39
A14: West | B14: =SUMIF('Raw Data'!K:K,A14,'Raw Data'!N:N) -> 41408.68
A15: Central | B15: =SUMIF('Raw Data'!K:K,A15,'Raw Data'!N:N) -> 41288.34
A17: Monthly Revenue Trend
A18: Month | B18: Revenue | C18: Orders
A19: Apr-24 | B19: =SUMPRODUCT((MONTH('Raw Data'!B$2:B$251)=4)*(YEAR('Raw Data'!B$2:B$251)=2024)*('Raw Data'!N$2:N$251)) -> 20919.33 | C19: =SUMPRODUCT((MONTH('Raw Data'!B$2:B$251)=4)*(YEAR('Raw Data'!B$2:B$251)=2024)*1) -> 21
A20: May-24 | B20: =SUMPRODUCT((MONTH('Raw Data'!B$2:B$251)=5)*(YEAR('Raw Data'!B$2:B$251)=2024)*('Raw Data'!N$2:N$251)) -> 17039.35 | C20: =SUMPRODUCT((MONTH('Raw Data'!B$2:B$251)=5)*(YEAR('Raw Data'!B$2:B$251)=2024)*1) -> 19
A21: Jun-24 | B21: =SUMPRODUCT((MONTH('Raw Data'!B$2:B$251)=6)*(YEAR('Raw Data'!B$2:B$251)=2024)*('Raw Data'!N$2:N$251)) -> 19299.45 | C21: =SUMPRODUCT((MONTH('Raw Data'!B$2:B$251)=6)*(YEAR('Raw Data'!B$2:B$251)=2024)*1) -> 19
A22: Jul-24 | B22: =SUMPRODUCT((MONTH('Raw Data'!B$2:B$251)=7)*(YEAR('Raw Data'!B$2:B$251)=2024)*('Raw Data'!N$2:N$251)) -> 18479.4 | C22: =SUMPRODUCT((MONTH('Raw Data'!B$2:B$251)=7)*(YEAR('Raw Data'!B$2:B$251)=2024)*1) -> 24
A23: Aug-24 | B23: =SUMPRODUCT((MONTH('Raw Data'!B$2:B$251)=8)*(YEAR('Raw Data'!B$2:B$251)=2024)*('Raw Data'!N$2:N$251)) -> 15759.43 | C23: =SUMPRODUCT((MONTH('Raw Data'!B$2:B$251)=8)*(YEAR('Raw Data'!B$2:B$251)=2024)*1) -> 18
A24: Sep-24 | B24: =SUMPRODUCT((MONTH('Raw Data'!B$2:B$251)=9)*(YEAR('Raw Data'!B$2:B$251)=2024)*('Raw Data'!N$2:N$251)) -> 12989.51 | C24: =SUMPRODUCT((MONTH('Raw Data'!B$2:B$251)=9)*(YEAR('Raw Data'!B$2:B$251)=2024)*1) -> 19
A25: Oct-24 | B25: =SUMPRODUCT((MONTH('Raw Data'!B$2:B$251)=10)*(YEAR('Raw Data'!B$2:B$251)=2024)*('Raw Data'!N$2:N$251)) -> 20609.52 | C25: =SUMPRODUCT((MONTH('Raw Data'!B$2:B$251)=10)*(YEAR('Raw Data'!B$2:B$251)=2024)*1) -> 16
A26: Nov-24 | B26: =SUMPRODUCT((MONTH('Raw Data'!B$2:B$251)=11)*(YEAR('Raw Data'!B$2:B$251)=2024)*('Raw Data'!N$2:N$251)) -> 12309.44 | C26: =SUMPRODUCT((MONTH('Raw Data'!B$2:B$251)=11)*(YEAR('Raw Data'!B$2:B$251)=2024)*1) -> 17
A27: Dec-24 | B27: =SUMPRODUCT((MONTH('Raw Data'!B$2:B$251)=12)*(YEAR('Raw Data'!B$2:B$251)=2024)*('Raw Data'!N$2:N$251)) -> 23039.3 | C27: =SUMPRODUCT((MONTH('Raw Data'!B$2:B$251)=12)*(YEAR('Raw Data'!B$2:B$251)=2024)*1) -> 25
A28: Jan-25 | B28: =SUMPRODUCT((MONTH('Raw Data'!B$2:B$251)=1)*(YEAR('Raw Data'!B$2:B$251)=2025)*('Raw Data'!N$2:N$251)) -> 25799.15 | C28: =SUMPRODUCT((MONTH('Raw Data'!B$2:B$251)=1)*(YEAR('Raw Data'!B$2:B$251)=2025)*1) -> 26
A29: Feb-25 | B29: =SUMPRODUCT((MONTH('Raw Data'!B$2:B$251)=2)*(YEAR('Raw Data'!B$2:B$251)=2025)*('Raw Data'!N$2:N$251)) -> 16069.38 | C29: =SUMPRODUCT((MONTH('Raw Data'!B$2:B$251)=2)*(YEAR('Raw Data'!B$2:B$251)=2025)*1) -> 20
A30: Mar-25 | B30: =SUMPRODUCT((MONTH('Raw Data'!B$2:B$251)=3)*(YEAR('Raw Data'!B$2:B$251)=2025)*('Raw Data'!N$2:N$251)) -> 19899.38 | C30: =SUMPRODUCT((MONTH('Raw Data'!B$2:B$251)=3)*(YEAR('Raw Data'!B$2:B$251)=2025)*1) -> 19
A31: Apr-25 | B31: =SUMPRODUCT((MONTH('Raw Data'!B$2:B$251)=4)*(YEAR('Raw Data'!B$2:B$251)=2025)*('Raw Data'!N$2:N$251)) -> 6979.83 | C31: =SUMPRODUCT((MONTH('Raw Data'!B$2:B$251)=4)*(YEAR('Raw Data'!B$2:B$251)=2025)*1) -> 7

Sheet Dashboard
A1: 📊 DATA INTELLIGENCE DASHBOARD | Customer Transaction Analysis | Apr 2024 – Apr 2025
A3: Last Refreshed: Use Analysis sheet for live timestamp
A5: 💰 TOTAL REVENUE | E5: 🧾 TOTAL ORDERS | I5: 👥 UNIQUE CUSTOMERS | M5: 📦 AVG ORDER VALUE
A6: =TEXT(SUM('Raw Data'!N:N),"$#,##0.00") -> $2,29,192.47 | E6: =TEXT(COUNTA('Raw Data'!A2:A251),"0") -> 249 | I6: {=TEXT(SUMPRODUCT(1/COUNTIF('Raw Data'!C2:C251,'Raw Data'!C2:C251)),"0")} -> 50 | M6: =TEXT(IFERROR(SUM('Raw Data'!N:N)/COUNTA('Raw Data'!A2:A251),0),"$#,##0.00") -> $920.45
A11: ⭐ PREMIUM REVENUE | E11: 🔷 STANDARD REVENUE | I11: 🔸 BASIC REVENUE | M11: 📈 TOP PRODUCT
A12: =TEXT(SUMIF('Raw Data'!L:L,"Premium",'Raw Data'!N:N),"$#,##0.00") -> $84,657.12 | E12: =TEXT(SUMIF('Raw Data'!L:L,"Standard",'Raw Data'!N:N),"$#,##0.00") -> $82,357.54 | I12: =TEXT(SUMIF('Raw Data'!L:L,"Basic",'Raw Data'!N:N),"$#,##0.00") -> $62,177.81 | M12: =INDEX('Raw Data'!F:F,MATCH(MAX(I12COUNTIF('Raw Data'!F2:F251,'Raw Data'!F2:F251)),COUNTIF('Raw Data'!F2:F251,'Raw Data'!F2:F251),0)+1) -> #NAME?
A17: 🏆 TOP PRODUCTS BY REVENUE | E17: 👑 TOP 5 CUSTOMERS BY SPEND | I17: 🗺️ REGIONAL PERFORMANCE | M17: 📊 CUSTOMER SEGMENT SPLIT
A18: Product | B18: Revenue | C18: Orders | D18: Avg Unit $ | E18: Customer | F18: Spent | G18: Orders | H18: Segment | I18: Region | J18: Revenue | K18: Orders | L18: Avg Ticket | M18: Segment | N18: Revenue | O18: Orders | P18: % Rev
A19: Laptop | B19: =SUMIF('Raw Data'!F:F,A19,'Raw Data'!N:N) -> 67499.25 | C19: =COUNTIF('Raw Data'!F:F,A19) -> 24 | D19: =IFERROR(B19/C19,0) -> 2812.4688 | E19: Mark Carter | F19: =SUMIF('Raw Data'!C:C,"CUST025",'Raw Data'!N:N) -> 15659.65 | G19: =COUNTIF('Raw Data'!C:C,"CUST025") -> 12 | H19: =IFERROR(INDEX('Raw Data'!L:L,MATCH("CUST025",'Raw Data'!C:C,0)),"") -> Premium | I19: North | J19: =SUMIF('Raw Data'!K:K,I19,'Raw Data'!N:N) -> 50808.31 | K19: =COUNTIF('Raw Data'!K:K,I19) -> 59 | L19: =IFERROR(J19/K19,0) -> 861.1578 | M19: Premium | N19: =SUMIF('Raw Data'!L:L,M19,'Raw Data'!N:N) -> 84657.12 | O19: =COUNTIF('Raw Data'!L:L,M19) -> 95 | P19: =IFERROR(N19/SUM(N19:N21),0) -> 0.3693713
A20: Smartphone | B20: =SUMIF('Raw Data'!F:F,A20,'Raw Data'!N:N) -> 67199.04 | C20: =COUNTIF('Raw Data'!F:F,A20) -> 31 | D20: =IFERROR(B20/C20,0) -> 2167.711 | E20: Patricia Moore | F20: =SUMIF('Raw Data'!C:C,"CUST012",'Raw Data'!N:N) -> 9799.73 | G20: =COUNTIF('Raw Data'!C:C,"CUST012") -> 8 | H20: =IFERROR(INDEX('Raw Data'!L:L,MATCH("CUST012",'Raw Data'!C:C,0)),"") -> Standard | I20: South | J20: =SUMIF('Raw Data'!K:K,I20,'Raw Data'!N:N) -> 36398.75 | K20: =COUNTIF('Raw Data'!K:K,I20) -> 42 | L20: =IFERROR(J20/K20,0) -> 866.6369 | M20: Standard | N20: =SUMIF('Raw Data'!L:L,M20,'Raw Data'!N:N) -> 82357.54 | O20: =COUNTIF('Raw Data'!L:L,M20) -> 81 | P20: =IFERROR(N20/SUM(N19:N21),0) -> 0.3593379
A21: Monitor | B21: =SUMIF('Raw Data'!F:F,A21,'Raw Data'!N:N) -> 21999.12 | C21: =COUNTIF('Raw Data'!F:F,A21) -> 26 | D21: =IFERROR(B21/C21,0) -> 846.12 | E21: Joseph Jackson | F21: =SUMIF('Raw Data'!C:C,"CUST013",'Raw Data'!N:N) -> 6949.84 | G21: =COUNTIF('Raw Data'!C:C,"CUST013") -> 5 | H21: =IFERROR(INDEX('Raw Data'!L:L,MATCH("CUST013",'Raw Data'!C:C,0)),"") -> Premium | I21: East | J21: =SUMIF('Raw Data'!K:K,I21,'Raw Data'!N:N) -> 59288.39 | K21: =COUNTIF('Raw Data'!K:K,I21) -> 48 | L21: =IFERROR(J21/K21,0) -> 1235.1748 | M21: Basic | N21: =SUMIF('Raw Data'!L:L,M21,'Raw Data'!N:N) -> 62177.81 | O21: =COUNTIF('Raw Data'!L:L,M21) -> 74 | P21: =IFERROR(N21/SUM(N19:N21),0) -> 0.27129081
A22: Desk | B22: =SUMIF('Raw Data'!F:F,A22,'Raw Data'!N:N) -> 23399.22 | C22: =COUNTIF('Raw Data'!F:F,A22) -> 26 | D22: =IFERROR(B22/C22,0) -> 899.97 | E22: Karen Hill | F22: =SUMIF('Raw Data'!C:C,"CUST026",'Raw Data'!N:N) -> 8009.77 | G22: =COUNTIF('Raw Data'!C:C,"CUST026") -> 8 | H22: =IFERROR(INDEX('Raw Data'!L:L,MATCH("CUST026",'Raw Data'!C:C,0)),"") -> Premium | I22: West | J22: =SUMIF('Raw Data'!K:K,I22,'Raw Data'!N:N) -> 41408.68 | K22: =COUNTIF('Raw Data'!K:K,I22) -> 47 | L22: =IFERROR(J22/K22,0) -> 881.03574
A23: Bookshelf | B23: =SUMIF('Raw Data'!F:F,A23,'Raw Data'!N:N) -> 15298.98 | C23: =COUNTIF('Raw Data'!F:F,A23) -> 35 | D23: =IFERROR(B23/C23,0) -> 437.11371 | E23: Helen Roberts | F23: =SUMIF('Raw Data'!C:C,"CUST030",'Raw Data'!N:N) -> 6459.79 | G23: =COUNTIF('Raw Data'!C:C,"CUST030") -> 7 | H23: =IFERROR(INDEX('Raw Data'!L:L,MATCH("CUST030",'Raw Data'!C:C,0)),"") -> Standard | I23: Central | J23: =SUMIF('Raw Data'!K:K,I23,'Raw Data'!N:N) -> 41288.34 | K23: =COUNTIF('Raw Data'!K:K,I23) -> 54 | L23: =IFERROR(J23/K23,0) -> 764.59889
A26: 📋 KEY INSIGHTS & STORYTELLING
A27: 🔍 Top Revenue Category | E27: 📍 Best Performing Region | I27: 💳 Preferred Payment Method | M27: 🧑 Highest-Value Customer Segment
A28: =INDEX({"Electronics","Furniture","Appliances"},MATCH(MAX(SUMIF('Raw Data'!G:G,{"Electronics","Furniture","Appliances"},'Raw Data'!N:N)),SUMIF('Raw Data'!G:G,{"Electronics","Furniture","Appliances"},'Raw Data'!N:N),0)) & " leads with $" & TEXT(MAX(SUMIF('Raw Data'!G:G,{"Electronics","Furniture","Appliances"},'Raw Data'!N:N)),"#,##0") -> Electronics leads with $1,71,756 | E28: =INDEX({"North","South","East","West","Central"},MATCH(MAX(SUMIF('Raw Data'!K:K,{"North","South","East","West","Central"},'Raw Data'!N:N)),SUMIF('Raw Data'!K:K,{"North","South","East","West","Central"},'Raw Data'!N:N),0)) & " region tops regional performance" -> East region tops regional performance | I28: =INDEX({"Cash","Credit Card","Debit Card","PayPal"},MATCH(MAX(COUNTIF('Raw Data'!J:J,{"Cash","Credit Card","Debit Card","PayPal"})),COUNTIF('Raw Data'!J:J,{"Cash","Credit Card","Debit Card","PayPal"}),0)) & " is the most-used payment method" -> Cash is the most-used payment method | M28: =INDEX({"Premium","Standard","Basic"},MATCH(MAX(SUMIF('Raw Data'!L:L,{"Premium","Standard","Basic"},'Raw Data'!N:N)),SUMIF('Raw Data'!L:L,{"Premium","Standard","Basic"},'Raw Data'!N:N),0)) & " segment drives the most revenue" -> Premium segment drives the most revenue
A31: 📉 LINEAR REGRESSION (Qty vs Revenue) — Use Data Analysis Toolpak in Excel on Raw Data tab
A32: Steps: Data → Data Analysis → Regression | Input Y: Total_Amount (Col N) | Input X: Quantity (Col H) | Output: New Sheet | Interpret R², Coefficients for forecasting

Sheet Summary Report
A1: EXECUTIVE SUMMARY REPORT — DATA INTELLIGENCE DASHBOARD
A2: Dataset: 250 Customer Transactions | Period: April 2024 – April 2025 | Source: Final Project Dataset
A4: KEY PERFORMANCE INDICATORS
A5: Total Revenue | B5: =TEXT(SUM('Raw Data'!N:N),"$#,##0.00") -> $2,29,192.47
A6: Total Transactions | B6: =TEXT(COUNTA('Raw Data'!A2:A251),"0") -> 249
A7: Unique Customers | B7: =TEXT(SUMPRODUCT(1/COUNTIF('Raw Data'!C2:C251,'Raw Data'!C2:C251)),"0") -> 50
A8: Average Order Value | B8: =TEXT(IFERROR(SUM('Raw Data'!N:N)/COUNTA('Raw Data'!A2:A251),0),"$#,##0.00") -> $920.45
A9: Top Category | B9: =INDEX({"Electronics","Furniture","Appliances"},MATCH(MAX(SUMIF('Raw Data'!G:G,{"Electronics","Furniture","Appliances"},'Raw Data'!N:N)),SUMIF('Raw Data'!G:G,{"Electronics","Furniture","Appliances"},'Raw Data'!N:N),0)) -> Electronics
A10: Most Frequent Product | B10: =INDEX('Raw Data'!F2:F251,MATCH(MAX(COUNTIF('Raw Data'!F2:F251,'Raw Data'!F2:F251)),COUNTIF('Raw Data'!F2:F251,'Raw Data'!F2:F251),0)) -> #N/A
A11: Best Region (by Revenue) | B11: =INDEX({"North","South","East","West","Central"},MATCH(MAX(SUMIF('Raw Data'!K:K,{"North","South","East","West","Central"},'Raw Data'!N:N)),SUMIF('Raw Data'!K:K,{"North","South","East","West","Central"},'Raw Data'!N:N),0)) -> East
A12: Top Payment Method | B12: =INDEX({"Cash","Credit Card","Debit Card","PayPal"},MATCH(MAX(COUNTIF('Raw Data'!J:J,{"Cash","Credit Card","Debit Card","PayPal"})),COUNTIF('Raw Data'!J:J,{"Cash","Credit Card","Debit Card","PayPal"}),0)) -> Cash
A14: ANALYSIS STORYTELLING & INSIGHTS
A15: Revenue Mix | B15: Electronics dominates revenue, driven by high-ticket items (Laptop @ $899.99, Smartphone @ $699.99). Furniture shows strong steady performance from Desks and Bookshelves. Appliances, while high in order volume (Blender, Coffee Maker), contribute lower total revenue due to lower unit prices.
A16: Customer Behavior | B16: Premium segment customers have the highest average order values. Repeat buyers like Mark Carter, Patricia Moore, and Karen Hill drive outsized revenue share. DATEDIF analysis shows long-tenured customers (Customer Since 2021) tend to place larger orders.
A17: Regional Insights | B17: All five regions show balanced participation. North and West lead in Electronics purchases. South shows strength in Furniture. Regional diversification reduces concentration risk for the business.
A18: Payment Preferences | B18: Credit Card is the most-used payment method, followed closely by Cash. PayPal is popular for higher-value Electronics purchases. Debit Card usage correlates with mid-range Furniture and Appliances purchases.
A19: Trend Analysis | B19: Monthly revenue shows a generally upward trend from Apr 2024. Peak months (Jun-Jul 2024, Dec 2024) align with seasonal demand. The Apr 2025 partial month data shows strong start suggesting continued growth.
A20: What-If Scenarios | B20: A 10% revenue growth target is achievable given current trajectory. Goal Seek analysis in the Analysis sheet identifies the exact growth rate needed to hit $100,000 revenue milestone. Scenario Manager allows modeling Optimistic (+20%), Base (+10%), and Pessimistic (-5%) cases.
A22: FORMULAS & FUNCTIONS USED IN THIS WORKBOOK
A23: Formula/Function | B23: Sheet | C23: Purpose | D23: Example
A24: TODAY(), NOW() | B24: Analysis | C24: Return today's date and current datetime | D24: Formula: =TODAY(), =NOW()
A25: DATEDIF() | B25: Analysis | C25: Calculate days/months/years between dates | D25: Formula: =DATEDIF(start_date, end_date, "D")
A26: EOMONTH() | B26: Analysis | C26: Find last day of a month offset | D26: Formula: =EOMONTH(TODAY(), 0)
A27: SUMIF() | B27: Analysis/Dashboard | C27: Sum values matching a criterion | D27: Formula: =SUMIF(range, criteria, sum_range)
A28: COUNTIF() | B28: Analysis/Dashboard | C28: Count cells matching a criterion | D28: Formula: =COUNTIF(range, criteria)
A29: SUMPRODUCT() | B29: Analysis | C29: Sum product of arrays (used for monthly data) | D29: Formula: =SUMPRODUCT((MONTH(dates)=4)*(amounts))
A30: INDEX/MATCH() | B30: Analysis/Dashboard | C30: Flexible lookup beyond VLOOKUP | D30: Formula: =INDEX(col, MATCH(val, col, 0))
A31: RANK() | B31: Analysis | C31: Rank products by frequency | D31: Formula: =RANK(B38, B38:B47, 0)
A32: IFERROR() | B32: All sheets | C32: Handle errors gracefully | D32: Formula: =IFERROR(formula, 0)
A33: TEXT() | B33: Dashboard/Summary | C33: Format numbers as text strings | D33: Formula: =TEXT(value, "Format")
A34: LEFT(), MID(), FIND() | B34: Analysis | C34: Create abbreviations from customer names | D34: Formula: =LEFT(name,1) & "." & MID(name, FIND(" ",name)+1, 1) & "."
... A38: Data Bar Cond. Format | B38: Analysis | C38: Show in-cell bar charts for orders | D38: Home > Conditional Formatting > Data Bars
